[2025-07-04T03:30:28.303+0000] {local_task_job_runner.py:120} INFO - ::group::Pre task execution logs
[2025-07-04T03:30:28.342+0000] {taskinstance.py:2076} INFO - Dependencies all met for dep_context=non-requeueable deps ti=<TaskInstance: products_prices_dag.transfrom_products scheduled__2025-07-03T00:00:00+00:00 [queued]>
[2025-07-04T03:30:28.360+0000] {taskinstance.py:2076} INFO - Dependencies all met for dep_context=requeueable deps ti=<TaskInstance: products_prices_dag.transfrom_products scheduled__2025-07-03T00:00:00+00:00 [queued]>
[2025-07-04T03:30:28.362+0000] {taskinstance.py:2306} INFO - Starting attempt 9 of 10
[2025-07-04T03:30:28.419+0000] {taskinstance.py:2330} INFO - Executing <Task(PythonOperator): transfrom_products> on 2025-07-03 00:00:00+00:00
[2025-07-04T03:30:28.429+0000] {standard_task_runner.py:63} INFO - Started process 654 to run task
[2025-07-04T03:30:28.439+0000] {standard_task_runner.py:90} INFO - Running: ['***', 'tasks', 'run', 'products_prices_dag', 'transfrom_products', 'scheduled__2025-07-03T00:00:00+00:00', '--job-id', '162', '--raw', '--subdir', 'DAGS_FOLDER/products_prices_dag.py', '--cfg-path', '/tmp/tmp57weqrkb']
[2025-07-04T03:30:28.446+0000] {standard_task_runner.py:91} INFO - Job 162: Subtask transfrom_products
[2025-07-04T03:30:28.488+0000] {logging_mixin.py:188} WARNING - /home/***/.local/lib/python3.10/site-packages/***/settings.py:195 DeprecationWarning: The sql_alchemy_conn option in [core] has been moved to the sql_alchemy_conn option in [database] - the old setting has been used, but please update your config.
[2025-07-04T03:30:28.621+0000] {task_command.py:426} INFO - Running <TaskInstance: products_prices_dag.transfrom_products scheduled__2025-07-03T00:00:00+00:00 [running]> on host e43ce2a1e7a4
[2025-07-04T03:30:29.006+0000] {taskinstance.py:2648} INFO - Exporting env vars: AIRFLOW_CTX_DAG_OWNER='karthik' AIRFLOW_CTX_DAG_ID='products_prices_dag' AIRFLOW_CTX_TASK_ID='transfrom_products' AIRFLOW_CTX_EXECUTION_DATE='2025-07-03T00:00:00+00:00' AIRFLOW_CTX_TRY_NUMBER='9' AIRFLOW_CTX_DAG_RUN_ID='scheduled__2025-07-03T00:00:00+00:00'
[2025-07-04T03:30:29.011+0000] {taskinstance.py:430} INFO - ::endgroup::
[2025-07-04T03:30:29.075+0000] {taskinstance.py:441} INFO - ::group::Post task execution logs
[2025-07-04T03:30:29.076+0000] {taskinstance.py:2905} ERROR - Task failed with exception
Traceback (most recent call last):
  File "/home/airflow/.local/lib/python3.10/site-packages/airflow/models/taskinstance.py", line 465, in _execute_task
    result = _execute_callable(context=context, **execute_callable_kwargs)
  File "/home/airflow/.local/lib/python3.10/site-packages/airflow/models/taskinstance.py", line 432, in _execute_callable
    return execute_callable(context=context, **execute_callable_kwargs)
  File "/home/airflow/.local/lib/python3.10/site-packages/airflow/models/baseoperator.py", line 401, in wrapper
    return func(self, *args, **kwargs)
  File "/home/airflow/.local/lib/python3.10/site-packages/airflow/operators/python.py", line 235, in execute
    return_value = self.execute_callable()
  File "/home/airflow/.local/lib/python3.10/site-packages/airflow/operators/python.py", line 252, in execute_callable
    return self.python_callable(*self.op_args, **self.op_kwargs)
  File "/opt/airflow/dags/scripts/fakestoreapi/get_products.py", line 46, in clean_products
    df.columns = ['product_id', 'product_name', 'price','category', 'description', 'image_link', 'rating', 'rating_count']
  File "/home/airflow/.local/lib/python3.10/site-packages/pandas/core/generic.py", line 6218, in __setattr__
    return object.__setattr__(self, name, value)
  File "properties.pyx", line 69, in pandas._libs.properties.AxisProperty.__set__
  File "/home/airflow/.local/lib/python3.10/site-packages/pandas/core/generic.py", line 767, in _set_axis
    self._mgr.set_axis(axis, labels)
  File "/home/airflow/.local/lib/python3.10/site-packages/pandas/core/internals/managers.py", line 227, in set_axis
    self._validate_set_axis(axis, new_labels)
  File "/home/airflow/.local/lib/python3.10/site-packages/pandas/core/internals/base.py", line 85, in _validate_set_axis
    raise ValueError(
ValueError: Length mismatch: Expected axis has 9 elements, new values have 8 elements
[2025-07-04T03:30:29.118+0000] {taskinstance.py:1206} INFO - Marking task as UP_FOR_RETRY. dag_id=products_prices_dag, task_id=transfrom_products, run_id=scheduled__2025-07-03T00:00:00+00:00, execution_date=20250703T000000, start_date=20250704T033028, end_date=20250704T033029
[2025-07-04T03:30:29.187+0000] {standard_task_runner.py:110} ERROR - Failed to execute job 162 for task transfrom_products (Length mismatch: Expected axis has 9 elements, new values have 8 elements; 654)
[2025-07-04T03:30:29.216+0000] {local_task_job_runner.py:240} INFO - Task exited with return code 1
[2025-07-04T03:30:29.244+0000] {taskinstance.py:3503} INFO - 0 downstream tasks scheduled from follow-on schedule check
[2025-07-04T03:30:29.253+0000] {local_task_job_runner.py:222} INFO - ::endgroup::
