[2025-07-02T11:03:13.515+0000] {local_task_job_runner.py:120} INFO - ::group::Pre task execution logs
[2025-07-02T11:03:13.556+0000] {taskinstance.py:2076} INFO - Dependencies all met for dep_context=non-requeueable deps ti=<TaskInstance: mysql_dag.insert_data scheduled__2025-06-30T00:00:00+00:00 [queued]>
[2025-07-02T11:03:13.570+0000] {taskinstance.py:2076} INFO - Dependencies all met for dep_context=requeueable deps ti=<TaskInstance: mysql_dag.insert_data scheduled__2025-06-30T00:00:00+00:00 [queued]>
[2025-07-02T11:03:13.571+0000] {taskinstance.py:2306} INFO - Starting attempt 1 of 2
[2025-07-02T11:03:13.593+0000] {taskinstance.py:2330} INFO - Executing <Task(PythonOperator): insert_data> on 2025-06-30 00:00:00+00:00
[2025-07-02T11:03:13.606+0000] {standard_task_runner.py:63} INFO - Started process 191 to run task
[2025-07-02T11:03:13.610+0000] {standard_task_runner.py:90} INFO - Running: ['***', 'tasks', 'run', 'mysql_dag', 'insert_data', 'scheduled__2025-06-30T00:00:00+00:00', '--job-id', '89', '--raw', '--subdir', 'DAGS_FOLDER/mysql.py', '--cfg-path', '/tmp/tmpqtlgczib']
[2025-07-02T11:03:13.617+0000] {standard_task_runner.py:91} INFO - Job 89: Subtask insert_data
[2025-07-02T11:03:13.655+0000] {logging_mixin.py:188} WARNING - /home/***/.local/lib/python3.10/site-packages/***/settings.py:195 DeprecationWarning: The sql_alchemy_conn option in [core] has been moved to the sql_alchemy_conn option in [database] - the old setting has been used, but please update your config.
[2025-07-02T11:03:13.800+0000] {task_command.py:426} INFO - Running <TaskInstance: mysql_dag.insert_data scheduled__2025-06-30T00:00:00+00:00 [running]> on host 76fc2b11611c
[2025-07-02T11:03:13.970+0000] {taskinstance.py:2648} INFO - Exporting env vars: AIRFLOW_CTX_DAG_OWNER='Karthik' AIRFLOW_CTX_DAG_ID='mysql_dag' AIRFLOW_CTX_TASK_ID='insert_data' AIRFLOW_CTX_EXECUTION_DATE='2025-06-30T00:00:00+00:00' AIRFLOW_CTX_TRY_NUMBER='1' AIRFLOW_CTX_DAG_RUN_ID='scheduled__2025-06-30T00:00:00+00:00'
[2025-07-02T11:03:13.972+0000] {taskinstance.py:430} INFO - ::endgroup::
[2025-07-02T11:03:14.163+0000] {taskinstance.py:441} INFO - ::group::Post task execution logs
[2025-07-02T11:03:14.164+0000] {taskinstance.py:2905} ERROR - Task failed with exception
Traceback (most recent call last):
  File "/home/airflow/.local/lib/python3.10/site-packages/airflow/models/taskinstance.py", line 465, in _execute_task
    result = _execute_callable(context=context, **execute_callable_kwargs)
  File "/home/airflow/.local/lib/python3.10/site-packages/airflow/models/taskinstance.py", line 432, in _execute_callable
    return execute_callable(context=context, **execute_callable_kwargs)
  File "/home/airflow/.local/lib/python3.10/site-packages/airflow/models/baseoperator.py", line 401, in wrapper
    return func(self, *args, **kwargs)
  File "/home/airflow/.local/lib/python3.10/site-packages/airflow/operators/python.py", line 235, in execute
    return_value = self.execute_callable()
  File "/home/airflow/.local/lib/python3.10/site-packages/airflow/operators/python.py", line 252, in execute_callable
    return self.python_callable(*self.op_args, **self.op_kwargs)
  File "/opt/airflow/dags/insert_data.py", line 15, in insert_data
    df = pd.read_csv("Output.csv")
  File "/home/airflow/.local/lib/python3.10/site-packages/pandas/io/parsers/readers.py", line 948, in read_csv
    return _read(filepath_or_buffer, kwds)
  File "/home/airflow/.local/lib/python3.10/site-packages/pandas/io/parsers/readers.py", line 611, in _read
    parser = TextFileReader(filepath_or_buffer, **kwds)
  File "/home/airflow/.local/lib/python3.10/site-packages/pandas/io/parsers/readers.py", line 1448, in __init__
    self._engine = self._make_engine(f, self.engine)
  File "/home/airflow/.local/lib/python3.10/site-packages/pandas/io/parsers/readers.py", line 1705, in _make_engine
    self.handles = get_handle(
  File "/home/airflow/.local/lib/python3.10/site-packages/pandas/io/common.py", line 863, in get_handle
    handle = open(
FileNotFoundError: [Errno 2] No such file or directory: 'Output.csv'
[2025-07-02T11:03:14.181+0000] {taskinstance.py:1206} INFO - Marking task as UP_FOR_RETRY. dag_id=mysql_dag, task_id=insert_data, run_id=scheduled__2025-06-30T00:00:00+00:00, execution_date=20250630T000000, start_date=20250702T110313, end_date=20250702T110314
[2025-07-02T11:03:14.199+0000] {standard_task_runner.py:110} ERROR - Failed to execute job 89 for task insert_data ([Errno 2] No such file or directory: 'Output.csv'; 191)
[2025-07-02T11:03:14.233+0000] {local_task_job_runner.py:240} INFO - Task exited with return code 1
[2025-07-02T11:03:14.246+0000] {local_task_job_runner.py:222} INFO - ::endgroup::
