[2025-07-04T04:06:26.822+0000] {local_task_job_runner.py:120} INFO - ::group::Pre task execution logs
[2025-07-04T04:06:27.036+0000] {taskinstance.py:2076} INFO - Dependencies all met for dep_context=non-requeueable deps ti=<TaskInstance: products_prices_dag.ETL_group.transfrom_products scheduled__2025-07-03T00:00:00+00:00 [queued]>
[2025-07-04T04:06:27.053+0000] {taskinstance.py:2076} INFO - Dependencies all met for dep_context=requeueable deps ti=<TaskInstance: products_prices_dag.ETL_group.transfrom_products scheduled__2025-07-03T00:00:00+00:00 [queued]>
[2025-07-04T04:06:27.054+0000] {taskinstance.py:2306} INFO - Starting attempt 6 of 7
[2025-07-04T04:06:27.115+0000] {taskinstance.py:2330} INFO - Executing <Task(PythonOperator): ETL_group.transfrom_products> on 2025-07-03 00:00:00+00:00
[2025-07-04T04:06:27.121+0000] {standard_task_runner.py:63} INFO - Started process 1892 to run task
[2025-07-04T04:06:27.125+0000] {standard_task_runner.py:90} INFO - Running: ['***', 'tasks', 'run', 'products_prices_dag', 'ETL_group.transfrom_products', 'scheduled__2025-07-03T00:00:00+00:00', '--job-id', '186', '--raw', '--subdir', 'DAGS_FOLDER/products_prices_dag.py', '--cfg-path', '/tmp/tmpdrzejdjq']
[2025-07-04T04:06:27.129+0000] {standard_task_runner.py:91} INFO - Job 186: Subtask ETL_group.transfrom_products
[2025-07-04T04:06:27.154+0000] {logging_mixin.py:188} WARNING - /home/***/.local/lib/python3.10/site-packages/***/settings.py:195 DeprecationWarning: The sql_alchemy_conn option in [core] has been moved to the sql_alchemy_conn option in [database] - the old setting has been used, but please update your config.
[2025-07-04T04:06:27.219+0000] {task_command.py:426} INFO - Running <TaskInstance: products_prices_dag.ETL_group.transfrom_products scheduled__2025-07-03T00:00:00+00:00 [running]> on host e43ce2a1e7a4
[2025-07-04T04:06:27.323+0000] {taskinstance.py:2648} INFO - Exporting env vars: AIRFLOW_CTX_DAG_OWNER='karthik' AIRFLOW_CTX_DAG_ID='products_prices_dag' AIRFLOW_CTX_TASK_ID='ETL_group.transfrom_products' AIRFLOW_CTX_EXECUTION_DATE='2025-07-03T00:00:00+00:00' AIRFLOW_CTX_TRY_NUMBER='6' AIRFLOW_CTX_DAG_RUN_ID='scheduled__2025-07-03T00:00:00+00:00'
[2025-07-04T04:06:27.324+0000] {taskinstance.py:430} INFO - ::endgroup::
[2025-07-04T04:06:27.359+0000] {taskinstance.py:441} INFO - ::group::Post task execution logs
[2025-07-04T04:06:27.360+0000] {taskinstance.py:2905} ERROR - Task failed with exception
Traceback (most recent call last):
  File "/home/airflow/.local/lib/python3.10/site-packages/airflow/models/taskinstance.py", line 465, in _execute_task
    result = _execute_callable(context=context, **execute_callable_kwargs)
  File "/home/airflow/.local/lib/python3.10/site-packages/airflow/models/taskinstance.py", line 432, in _execute_callable
    return execute_callable(context=context, **execute_callable_kwargs)
  File "/home/airflow/.local/lib/python3.10/site-packages/airflow/models/baseoperator.py", line 401, in wrapper
    return func(self, *args, **kwargs)
  File "/home/airflow/.local/lib/python3.10/site-packages/airflow/operators/python.py", line 235, in execute
    return_value = self.execute_callable()
  File "/home/airflow/.local/lib/python3.10/site-packages/airflow/operators/python.py", line 252, in execute_callable
    return self.python_callable(*self.op_args, **self.op_kwargs)
  File "/opt/airflow/dags/scripts/fakestoreapi/get_products.py", line 42, in clean_products
    df = pd.read_csv(f'{path}raw_output.csv')
  File "/home/airflow/.local/lib/python3.10/site-packages/pandas/io/parsers/readers.py", line 948, in read_csv
    return _read(filepath_or_buffer, kwds)
  File "/home/airflow/.local/lib/python3.10/site-packages/pandas/io/parsers/readers.py", line 611, in _read
    parser = TextFileReader(filepath_or_buffer, **kwds)
  File "/home/airflow/.local/lib/python3.10/site-packages/pandas/io/parsers/readers.py", line 1448, in __init__
    self._engine = self._make_engine(f, self.engine)
  File "/home/airflow/.local/lib/python3.10/site-packages/pandas/io/parsers/readers.py", line 1723, in _make_engine
    return mapping[engine](f, **self.options)
  File "/home/airflow/.local/lib/python3.10/site-packages/pandas/io/parsers/c_parser_wrapper.py", line 93, in __init__
    self._reader = parsers.TextReader(src, **kwds)
  File "parsers.pyx", line 579, in pandas._libs.parsers.TextReader.__cinit__
  File "parsers.pyx", line 668, in pandas._libs.parsers.TextReader._get_header
  File "parsers.pyx", line 879, in pandas._libs.parsers.TextReader._tokenize_rows
  File "parsers.pyx", line 890, in pandas._libs.parsers.TextReader._check_tokenize_status
  File "parsers.pyx", line 2050, in pandas._libs.parsers.raise_parser_error
OSError: [Errno 5] Input/output error
[2025-07-04T04:06:27.378+0000] {taskinstance.py:1206} INFO - Marking task as UP_FOR_RETRY. dag_id=products_prices_dag, task_id=ETL_group.transfrom_products, run_id=scheduled__2025-07-03T00:00:00+00:00, execution_date=20250703T000000, start_date=20250704T040627, end_date=20250704T040627
[2025-07-04T04:06:27.394+0000] {standard_task_runner.py:110} ERROR - Failed to execute job 186 for task ETL_group.transfrom_products ([Errno 5] Input/output error; 1892)
[2025-07-04T04:06:27.419+0000] {local_task_job_runner.py:240} INFO - Task exited with return code 1
[2025-07-04T04:06:27.445+0000] {taskinstance.py:3503} INFO - 0 downstream tasks scheduled from follow-on schedule check
[2025-07-04T04:06:27.449+0000] {local_task_job_runner.py:222} INFO - ::endgroup::
