[2025-07-04T04:05:04.669+0000] {local_task_job_runner.py:120} INFO - ::group::Pre task execution logs
[2025-07-04T04:05:04.854+0000] {taskinstance.py:2076} INFO - Dependencies all met for dep_context=non-requeueable deps ti=<TaskInstance: products_prices_dag.ETL_group.transfrom_products scheduled__2025-07-03T00:00:00+00:00 [queued]>
[2025-07-04T04:05:04.867+0000] {taskinstance.py:2076} INFO - Dependencies all met for dep_context=requeueable deps ti=<TaskInstance: products_prices_dag.ETL_group.transfrom_products scheduled__2025-07-03T00:00:00+00:00 [queued]>
[2025-07-04T04:05:04.868+0000] {taskinstance.py:2306} INFO - Starting attempt 4 of 6
[2025-07-04T04:05:04.885+0000] {taskinstance.py:2330} INFO - Executing <Task(PythonOperator): ETL_group.transfrom_products> on 2025-07-03 00:00:00+00:00
[2025-07-04T04:05:04.893+0000] {standard_task_runner.py:63} INFO - Started process 1850 to run task
[2025-07-04T04:05:04.898+0000] {standard_task_runner.py:90} INFO - Running: ['***', 'tasks', 'run', 'products_prices_dag', 'ETL_group.transfrom_products', 'scheduled__2025-07-03T00:00:00+00:00', '--job-id', '184', '--raw', '--subdir', 'DAGS_FOLDER/products_prices_dag.py', '--cfg-path', '/tmp/tmpqkvhpf_4']
[2025-07-04T04:05:04.901+0000] {standard_task_runner.py:91} INFO - Job 184: Subtask ETL_group.transfrom_products
[2025-07-04T04:05:04.923+0000] {logging_mixin.py:188} WARNING - /home/***/.local/lib/python3.10/site-packages/***/settings.py:195 DeprecationWarning: The sql_alchemy_conn option in [core] has been moved to the sql_alchemy_conn option in [database] - the old setting has been used, but please update your config.
[2025-07-04T04:05:04.986+0000] {task_command.py:426} INFO - Running <TaskInstance: products_prices_dag.ETL_group.transfrom_products scheduled__2025-07-03T00:00:00+00:00 [running]> on host e43ce2a1e7a4
[2025-07-04T04:05:05.096+0000] {taskinstance.py:2648} INFO - Exporting env vars: AIRFLOW_CTX_DAG_OWNER='karthik' AIRFLOW_CTX_DAG_ID='products_prices_dag' AIRFLOW_CTX_TASK_ID='ETL_group.transfrom_products' AIRFLOW_CTX_EXECUTION_DATE='2025-07-03T00:00:00+00:00' AIRFLOW_CTX_TRY_NUMBER='4' AIRFLOW_CTX_DAG_RUN_ID='scheduled__2025-07-03T00:00:00+00:00'
[2025-07-04T04:05:05.098+0000] {taskinstance.py:430} INFO - ::endgroup::
[2025-07-04T04:05:05.147+0000] {taskinstance.py:441} INFO - ::group::Post task execution logs
[2025-07-04T04:05:05.149+0000] {taskinstance.py:2905} ERROR - Task failed with exception
Traceback (most recent call last):
  File "/home/airflow/.local/lib/python3.10/site-packages/airflow/models/taskinstance.py", line 465, in _execute_task
    result = _execute_callable(context=context, **execute_callable_kwargs)
  File "/home/airflow/.local/lib/python3.10/site-packages/airflow/models/taskinstance.py", line 432, in _execute_callable
    return execute_callable(context=context, **execute_callable_kwargs)
  File "/home/airflow/.local/lib/python3.10/site-packages/airflow/models/baseoperator.py", line 401, in wrapper
    return func(self, *args, **kwargs)
  File "/home/airflow/.local/lib/python3.10/site-packages/airflow/operators/python.py", line 235, in execute
    return_value = self.execute_callable()
  File "/home/airflow/.local/lib/python3.10/site-packages/airflow/operators/python.py", line 252, in execute_callable
    return self.python_callable(*self.op_args, **self.op_kwargs)
  File "/opt/airflow/dags/scripts/fakestoreapi/get_products.py", line 44, in clean_products
    df['rating'] = df['rating'].apply(ast.literal_eval)
  File "/home/airflow/.local/lib/python3.10/site-packages/pandas/core/series.py", line 4764, in apply
    ).apply()
  File "/home/airflow/.local/lib/python3.10/site-packages/pandas/core/apply.py", line 1209, in apply
    return self.apply_standard()
  File "/home/airflow/.local/lib/python3.10/site-packages/pandas/core/apply.py", line 1289, in apply_standard
    mapped = obj._map_values(
  File "/home/airflow/.local/lib/python3.10/site-packages/pandas/core/base.py", line 921, in _map_values
    return algorithms.map_array(arr, mapper, na_action=na_action, convert=convert)
  File "/home/airflow/.local/lib/python3.10/site-packages/pandas/core/algorithms.py", line 1814, in map_array
    return lib.map_infer(values, mapper, convert=convert)
  File "lib.pyx", line 2926, in pandas._libs.lib.map_infer
  File "/usr/local/lib/python3.10/ast.py", line 110, in literal_eval
    return _convert(node_or_string)
  File "/usr/local/lib/python3.10/ast.py", line 109, in _convert
    return _convert_signed_num(node)
  File "/usr/local/lib/python3.10/ast.py", line 83, in _convert_signed_num
    return _convert_num(node)
  File "/usr/local/lib/python3.10/ast.py", line 74, in _convert_num
    _raise_malformed_node(node)
  File "/usr/local/lib/python3.10/ast.py", line 71, in _raise_malformed_node
    raise ValueError(msg + f': {node!r}')
ValueError: malformed node or string: 3.9
[2025-07-04T04:05:05.179+0000] {taskinstance.py:1206} INFO - Marking task as UP_FOR_RETRY. dag_id=products_prices_dag, task_id=ETL_group.transfrom_products, run_id=scheduled__2025-07-03T00:00:00+00:00, execution_date=20250703T000000, start_date=20250704T040504, end_date=20250704T040505
[2025-07-04T04:05:05.195+0000] {standard_task_runner.py:110} ERROR - Failed to execute job 184 for task ETL_group.transfrom_products (malformed node or string: 3.9; 1850)
[2025-07-04T04:05:05.232+0000] {local_task_job_runner.py:240} INFO - Task exited with return code 1
[2025-07-04T04:05:05.260+0000] {taskinstance.py:3503} INFO - 0 downstream tasks scheduled from follow-on schedule check
[2025-07-04T04:05:05.266+0000] {local_task_job_runner.py:222} INFO - ::endgroup::
