[2025-07-04T05:05:05.236+0000] {local_task_job_runner.py:120} INFO - ::group::Pre task execution logs
[2025-07-04T05:05:05.269+0000] {taskinstance.py:2076} INFO - Dependencies all met for dep_context=non-requeueable deps ti=<TaskInstance: products_prices_dag.mail_grp.alert_email scheduled__2025-07-03T00:00:00+00:00 [queued]>
[2025-07-04T05:05:05.286+0000] {taskinstance.py:2076} INFO - Dependencies all met for dep_context=requeueable deps ti=<TaskInstance: products_prices_dag.mail_grp.alert_email scheduled__2025-07-03T00:00:00+00:00 [queued]>
[2025-07-04T05:05:05.287+0000] {taskinstance.py:2306} INFO - Starting attempt 2 of 3
[2025-07-04T05:05:05.314+0000] {taskinstance.py:2330} INFO - Executing <Task(EmailOperator): mail_grp.alert_email> on 2025-07-03 00:00:00+00:00
[2025-07-04T05:05:05.327+0000] {standard_task_runner.py:63} INFO - Started process 3857 to run task
[2025-07-04T05:05:05.334+0000] {standard_task_runner.py:90} INFO - Running: ['***', 'tasks', 'run', 'products_prices_dag', 'mail_grp.alert_email', 'scheduled__2025-07-03T00:00:00+00:00', '--job-id', '208', '--raw', '--subdir', 'DAGS_FOLDER/products_prices_dag.py', '--cfg-path', '/tmp/tmp_n8yhlxw']
[2025-07-04T05:05:05.341+0000] {standard_task_runner.py:91} INFO - Job 208: Subtask mail_grp.alert_email
[2025-07-04T05:05:05.383+0000] {logging_mixin.py:188} WARNING - /home/***/.local/lib/python3.10/site-packages/***/settings.py:195 DeprecationWarning: The sql_alchemy_conn option in [core] has been moved to the sql_alchemy_conn option in [database] - the old setting has been used, but please update your config.
[2025-07-04T05:05:05.475+0000] {task_command.py:426} INFO - Running <TaskInstance: products_prices_dag.mail_grp.alert_email scheduled__2025-07-03T00:00:00+00:00 [running]> on host e43ce2a1e7a4
[2025-07-04T05:05:05.660+0000] {taskinstance.py:2648} INFO - Exporting env vars: AIRFLOW_CTX_DAG_OWNER='karthik' AIRFLOW_CTX_DAG_ID='products_prices_dag' AIRFLOW_CTX_TASK_ID='mail_grp.alert_email' AIRFLOW_CTX_EXECUTION_DATE='2025-07-03T00:00:00+00:00' AIRFLOW_CTX_TRY_NUMBER='2' AIRFLOW_CTX_DAG_RUN_ID='scheduled__2025-07-03T00:00:00+00:00'
[2025-07-04T05:05:05.663+0000] {taskinstance.py:430} INFO - ::endgroup::
[2025-07-04T05:05:05.711+0000] {base.py:84} INFO - Using connection ID 'email_conn' for task execution.
[2025-07-04T05:05:05.713+0000] {email.py:271} INFO - Email alerting: attempt 1
[2025-07-04T05:05:05.715+0000] {taskinstance.py:441} INFO - ::group::Post task execution logs
[2025-07-04T05:05:05.717+0000] {taskinstance.py:2905} ERROR - Task failed with exception
Traceback (most recent call last):
  File "/home/airflow/.local/lib/python3.10/site-packages/airflow/models/taskinstance.py", line 465, in _execute_task
    result = _execute_callable(context=context, **execute_callable_kwargs)
  File "/home/airflow/.local/lib/python3.10/site-packages/airflow/models/taskinstance.py", line 432, in _execute_callable
    return execute_callable(context=context, **execute_callable_kwargs)
  File "/home/airflow/.local/lib/python3.10/site-packages/airflow/models/baseoperator.py", line 401, in wrapper
    return func(self, *args, **kwargs)
  File "/home/airflow/.local/lib/python3.10/site-packages/airflow/operators/email.py", line 79, in execute
    send_email(
  File "/home/airflow/.local/lib/python3.10/site-packages/airflow/utils/email.py", line 80, in send_email
    return backend(
  File "/home/airflow/.local/lib/python3.10/site-packages/airflow/utils/email.py", line 154, in send_email_smtp
    send_mime_email(e_from=mail_from, e_to=recipients, mime_msg=msg, conn_id=conn_id, dryrun=dryrun)
  File "/home/airflow/.local/lib/python3.10/site-packages/airflow/utils/email.py", line 273, in send_mime_email
    smtp_conn = _get_smtp_connection(smtp_host, smtp_port, smtp_timeout, smtp_ssl)
  File "/home/airflow/.local/lib/python3.10/site-packages/airflow/utils/email.py", line 317, in _get_smtp_connection
    return smtplib.SMTP(host=host, port=port, timeout=timeout)
  File "/usr/local/lib/python3.10/smtplib.py", line 255, in __init__
    (code, msg) = self.connect(host, port)
  File "/usr/local/lib/python3.10/smtplib.py", line 341, in connect
    self.sock = self._get_socket(host, port, self.timeout)
  File "/usr/local/lib/python3.10/smtplib.py", line 312, in _get_socket
    return socket.create_connection((host, port), timeout,
  File "/usr/local/lib/python3.10/socket.py", line 845, in create_connection
    raise err
  File "/usr/local/lib/python3.10/socket.py", line 833, in create_connection
    sock.connect(sa)
ConnectionRefusedError: [Errno 111] Connection refused
[2025-07-04T05:05:05.738+0000] {taskinstance.py:1206} INFO - Marking task as UP_FOR_RETRY. dag_id=products_prices_dag, task_id=mail_grp.alert_email, run_id=scheduled__2025-07-03T00:00:00+00:00, execution_date=20250703T000000, start_date=20250704T050505, end_date=20250704T050505
[2025-07-04T05:05:05.796+0000] {standard_task_runner.py:110} ERROR - Failed to execute job 208 for task mail_grp.alert_email ([Errno 111] Connection refused; 3857)
[2025-07-04T05:05:05.831+0000] {local_task_job_runner.py:240} INFO - Task exited with return code 1
[2025-07-04T05:05:05.875+0000] {taskinstance.py:3503} INFO - 0 downstream tasks scheduled from follow-on schedule check
[2025-07-04T05:05:05.883+0000] {local_task_job_runner.py:222} INFO - ::endgroup::
